Workbook

Sheet Summary (2)
B1: LIST INVESTASI
C3: Close
C4: Delivered
C5: Partial Delivery
C6: Open
E7: =Detail!E2 -> 4 | G7: =Detail!F2 -> 5 | H7: =Detail!G2 -> 6 | I7: =Detail!H2 -> 7 | K7: =Detail!I2 -> 8
A8: NO | B8: No. PO | C8: Date | D8: Nama Barang | E8: =Detail!E3 -> Qty | F8: Harga Beli (only added if Margin is set) | G8: =Detail!F3 -> Harga | H8: Total PO | I8: Modal | J8: Margin Per Unit | K8: =Detail!I3 -> Margin | L8: Add Margin | M8: Total Margin | N8: Invoice /DO | U8: DO Total | V8: DO Outstanding | W8: Margin | X8: AR MARGIN | Y8: Del Time | Z8: Invoice date | AA8: Initial Payment Date | AB8: adjusting TOP 60 Days | AC8: Status | AD8: Notes
N9: Jul | O9: Aug | P9: Sep | Q9: Oct | R9: Nov | S9: Dec | T9: Add Margin (by Agreement) | AD9: Notes
A10: 1 | B10: 5200954145 | C10: =VLOOKUP($B10,Detail!$B$4:$Q$21,2,0) -> 45839 | D10: Top Frame 800 | E10: =SUMIF(Detail!$B$4:$B$21,'Summary (2)'!$B10,Detail!$E$4:$E$21) -> 2 | G10: =VLOOKUP($B10,Detail!$B$4:$Q$21,5,0) -> 225000000 | H10: =E10*G10 -> 450000000 | I10: =SUMIF(Detail!$B$4:$B$21,'Summary (2)'!B10,Detail!$H$4:$H$21) -> 225000000 | J10: =(I10*20%)/E10 -> 22500000 | K10: =I10*20% -> 45000000 | M10: =SUM(K10:L10) -> 45000000 | N10: =E10 -> 2 | U10: =SUM(N10:S10) -> 2 | V10: =E10-U10 -> 0 | W10: =J10*U10 -> 45000000 | X10: =K10-W10 -> 0 | Y10: 45861 | Z10: 45863 | AA10: 45894 | AC10: Close
A11: 2 | B11: 5200954149 | C11: =VLOOKUP($B11,Detail!$B$4:$Q$21,2,0) -> 45839 | D11: Top Frame 800 | E11: =SUMIF(Detail!$B$4:$B$21,'Summary (2)'!$B11,Detail!$E$4:$E$21) -> 3 | G11: =VLOOKUP($B11,Detail!$B$4:$Q$21,5,0) -> 225000000 | H11: =E11*G11 -> 675000000 | I11: =SUMIF(Detail!$B$4:$B$21,'Summary (2)'!B11,Detail!$H$4:$H$21) -> 337500000 | J11: =(I11*20%)/E11 -> 22500000 | K11: =I11*20% -> 67500000 | M11: =SUM(K11:L11) -> 67500000 | N11: =E11 -> 3 | U11: =SUM(N11:S11) -> 3 | V11: =E11-U11 -> 0 | W11: =J11*U11 -> 67500000 | X11: =K11-W11 -> 0 | Y11: 45861 | Z11: 45863 | AA11: 45894 | AC11: Close
A12: 3 | B12: 5200954160 | C12: =VLOOKUP($B12,Detail!$B$4:$Q$21,2,0) -> 45839 | D12: Top Frame 800 | E12: =SUMIF(Detail!$B$4:$B$21,'Summary (2)'!$B12,Detail!$E$4:$E$21) -> 3 | G12: =VLOOKUP($B12,Detail!$B$4:$Q$21,5,0) -> 225000000 | H12: =E12*G12 -> 675000000 | I12: =SUMIF(Detail!$B$4:$B$21,'Summary (2)'!B12,Detail!$H$4:$H$21) -> 337500000 | J12: =(I12*20%)/E12 -> 22500000 | K12: =I12*20% -> 67500000 | M12: =SUM(K12:L12) -> 67500000 | N12: =E12 -> 3 | U12: =SUM(N12:S12) -> 3 | V12: =E12-U12 -> 0 | W12: =J12*U12 -> 67500000 | X12: =K12-W12 -> 0 | Y12: 45861 | Z12: 45863 | AA12: 45894 | AC12: Close
A13: 4 | B13: 5200954165 | C13: =VLOOKUP($B13,Detail!$B$4:$Q$21,2,0) -> 45870 | D13: Top Frame 800 | E13: =SUMIF(Detail!$B$4:$B$21,'Summary (2)'!$B13,Detail!$E$4:$E$21) -> 3 | G13: =VLOOKUP($B13,Detail!$B$4:$Q$21,5,0) -> 225000000 | H13: =E13*G13 -> 675000000 | I13: =SUMIF(Detail!$B$4:$B$21,'Summary (2)'!B13,Detail!$H$4:$H$21) -> 337500000 | J13: =(I13*20%)/E13 -> 22500000 | K13: =I13*20% -> 67500000 | M13: =SUM(K13:L13) -> 67500000 | O13: =E13 -> 3 | U13: =SUM(N13:S13) -> 3 | V13: =E13-U13 -> 0 | W13: =J13*U13 -> 67500000 | X13: =K13-W13 -> 0 | Y13: 45868 | Z13: 45873 | AA13: 45904 | AC13: Close
A14: 5 | B14: 5200954167 | C14: =VLOOKUP($B14,Detail!$B$4:$Q$21,2,0) -> 45870 | D14: Top Frame 800 | E14: =SUMIF(Detail!$B$4:$B$21,'Summary (2)'!$B14,Detail!$E$4:$E$21) -> 3 | G14: =VLOOKUP($B14,Detail!$B$4:$Q$21,5,0) -> 225000000 | H14: =E14*G14 -> 675000000 | I14: =SUMIF(Detail!$B$4:$B$21,'Summary (2)'!B14,Detail!$H$4:$H$21) -> 337500000 | J14: =(I14*20%)/E14 -> 22500000 | K14: =I14*20% -> 67500000 | M14: =SUM(K14:L14) -> 67500000 | O14: =E14 -> 3 | U14: =SUM(N14:S14) -> 3 | V14: =E14-U14 -> 0 | W14: =J14*U14 -> 67500000 | X14: =K14-W14 -> 0 | Y14: 45868 | Z14: 45873 | AA14: 45904 | AC14: Close
A15: 6 | B15: 5200954168 | C15: =VLOOKUP($B15,Detail!$B$4:$Q$21,2,0) -> 45870 | D15: Top Frame 800 | E15: =SUMIF(Detail!$B$4:$B$21,'Summary (2)'!$B15,Detail!$E$4:$E$21) -> 2 | G15: =VLOOKUP($B15,Detail!$B$4:$Q$21,5,0) -> 225000000 | H15: =E15*G15 -> 450000000 | I15: =SUMIF(Detail!$B$4:$B$21,'Summary (2)'!B15,Detail!$H$4:$H$21) -> 225000000 | J15: =(I15*20%)/E15 -> 22500000 | K15: =I15*20% -> 45000000 | M15: =SUM(K15:L15) -> 45000000 | O15: =E15 -> 2 | U15: =SUM(N15:S15) -> 2 | V15: =E15-U15 -> 0 | W15: =J15*U15 -> 45000000 | X15: =K15-W15 -> 0 | Y15: 45868 | Z15: 45873 | AA15: 45904 | AC15: Close
A16: 7 | B16: 5200954169 | C16: =VLOOKUP($B16,Detail!$B$4:$Q$21,2,0) -> 45870 | D16: Top Frame 800 | E16: =SUMIF(Detail!$B$4:$B$21,'Summary (2)'!$B16,Detail!$E$4:$E$21) -> 2 | G16: =VLOOKUP($B16,Detail!$B$4:$Q$21,5,0) -> 225000000 | H16: =E16*G16 -> 450000000 | I16: =SUMIF(Detail!$B$4:$B$21,'Summary (2)'!B16,Detail!$H$4:$H$21) -> 225000000 | J16: =(I16*20%)/E16 -> 22500000 | K16: =I16*20% -> 45000000 | M16: =SUM(K16:L16) -> 45000000 | O16: =E16 -> 2 | U16: =SUM(N16:S16) -> 2 | V16: =E16-U16 -> 0 | W16: =J16*U16 -> 45000000 | X16: =K16-W16 -> 0 | Y16: 45868 | Z16: 45873 | AA16: 45904 | AC16: Close
A17: 8 | B17: 5200777098 | C17: =VLOOKUP($B17,Detail!$B$4:$Q$25,2,0) -> 45877 | D17: DVAR 3771-B0-20D-PPC Statcom Steel Support | E17: =SUMIF(Detail!$B$4:$B$25,'Summary (2)'!$B17,Detail!$E$4:$E$25) -> 1 | G17: =VLOOKUP($B17,Detail!$B$4:$Q$25,5,0) -> 1149199000 | H17: =E17*G17 -> 1149199000 | I17: =SUMIF(Detail!$B$4:$B$25,'Summary (2)'!B17,Detail!$H$4:$H$25) -> 574599500 | J17: =(I17*20%)/E17 -> 114919900 | K17: =I17*20% -> 114919900 | M17: =SUM(K17:L17) -> 114919900 | O17: 0 | P17: 1 | U17: =SUM(N17:S17) -> 1 | V17: =E17-U17 -> 0 | W17: =J17*U17 -> 114919900 | X17: =K17-W17 -> 0 | Y17: 45930 | Z17: =Y17+7 -> 45937 | AA17: =Z17+30 -> 45967 | AB17: =Z17+60 -> 45997 | AC17: Delivered
A18: 9 | B18: 5200776987 | C18: =VLOOKUP($B18,Detail!$B$4:$Q$25,2,0) -> 45877 | D18: Top Frame 800 | E18: =SUMIF(Detail!$B$4:$B$25,'Summary (2)'!$B18,Detail!$E$4:$E$25) -> 2 | G18: =VLOOKUP($B18,Detail!$B$4:$Q$25,5,0) -> 225000000 | H18: =E18*G18 -> 450000000 | I18: =SUMIF(Detail!$B$4:$B$25,'Summary (2)'!B18,Detail!$H$4:$H$25) -> 225000000 | J18: =(I18*20%)/E18 -> 22500000 | K18: =I18*20% -> 45000000 | M18: =SUM(K18:L18) -> 45000000 | O18: 0 | P18: 2 | U18: =SUM(N18:S18) -> 2 | V18: =E18-U18 -> 0 | W18: =J18*U18 -> 45000000 | X18: =K18-W18 -> 0 | Y18: 45923 | Z18: =Y18+7 -> 45930 | AA18: =Z18+30 -> 45960 | AB18: =Z18+60 -> 45990 | AC18: Delivered
A19: 10 | B19: 5200777132 | C19: =VLOOKUP($B19,Detail!$B$4:$Q$110,2,0) -> 45880 | D19: Leser Barrier MK 01-F3004973 | E19: 20 | G19: =VLOOKUP($B19,Detail!$B$4:$Q$25,5,0) -> 40457500 | H19: =E19*G19 -> 809150000 | I19: =H19*50% -> 404575000 | J19: =(I19*13%)/E19 -> 2629737.5 | K19: =I19*13% -> 52594750 | M19: =SUM(K19:L19) -> 52594750 | O19: 0 | U19: =SUM(N19:S19) -> 0 | V19: =E19-U19 -> 20 | W19: =J19*U19 -> 0 | X19: =K19-W19 -> 52594750 | Y19: 45922 | Z19: =Y19+7 -> 45929 | AA19: =Z19+30 -> 45959 | AB19: =Z19+60 -> 45989 | AC19: Open
A20: 11 | B20: =Detail!$B$45 -> 5200972695 | C20: =Detail!$C$45 -> 45891 | D20: Tangki | E20: 8 | F20: 75000000 | G20: 100500000 | H20: =E20*G20 -> 804000000 | I20: =H20*50% -> 402000000 | J20: 12750000 | K20: =E20*J20 -> 102000000 | M20: =SUM(K20:L20) -> 102000000 | O20: 0 | P20: 8 | T20: Margin was arranged 25mil/ea | U20: =SUM(N20:S20) -> 8 | V20: =E20-U20 -> 0 | W20: =J20*U20 -> 102000000 | X20: =K20-W20 -> 0 | Y20: 45925 | Z20: =Y20+7 -> 45932 | AA20: =Z20+30 -> 45962 | AB20: =Z20+60 -> 45992 | AC20: Delivered
A21: 12 | B21: =Detail!B53 -> 5200777558 | C21: 45901 | D21: Top Frame 2630 | E21: 1 | G21: =Detail!F53 -> 685000000 | H21: =E21*G21 -> 685000000 | I21: =H21*50% -> 342500000 | J21: =(I21*20%)/E21 -> 68500000 | K21: =I21*20% -> 68500000 | M21: =SUM(K21:L21) -> 68500000 | P21: 1 | U21: =SUM(N21:S21) -> 1 | V21: =E21-U21 -> 0 | W21: =J21*U21 -> 68500000 | X21: =K21-W21 -> 0 | Y21: 45923 | Z21: =Y21+7 -> 45930 | AA21: =Z21+30 -> 45960 | AB21: =Z21+60 -> 45990 | AC21: Delivered
A22: 13 | B22: =Detail!B54 -> 5200777559 | C22: 45901 | D22: Top Frame 800 | E22: 2 | G22: =Detail!F54 -> 225000000 | H22: =E22*G22 -> 450000000 | I22: =H22*50% -> 225000000 | J22: =(I22*20%)/E22 -> 22500000 | K22: =I22*20% -> 45000000 | M22: =SUM(K22:L22) -> 45000000 | P22: 2 | U22: =SUM(N22:S22) -> 2 | V22: =E22-U22 -> 0 | W22: =J22*U22 -> 45000000 | X22: =K22-W22 -> 0 | Y22: 45925 | Z22: =Y22+7 -> 45932 | AA22: =Z22+30 -> 45962 | AB22: =Z22+60 -> 45992 | AC22: Delivered
A23: 14 | B23: =Detail!$B$56 -> 5200777758 | C23: 45909 | D23: Pipe Spool | E23: 1 | G23: =Detail!F56 -> 2231048200 | H23: =E23*G23 -> 2231048200 | I23: =H23*50% -> 1115524100 | J23: =(I23*20%)/E23 -> 223104820 | K23: =I23*20% -> 223104820 | M23: =SUM(K23:L23) -> 223104820 | P23: 1 | U23: =SUM(N23:S23) -> 1 | V23: =E23-U23 -> 0 | W23: =J23*U23 -> 223104820 | X23: =K23-W23 -> 0 | Y23: 45930 | Z23: =Y23+7 -> 45937 | AA23: =Z23+30 -> 45967 | AB23: =Z23+60 -> 45997 | AC23: Delivered
A24: 15 | B24: =Detail!$B$58 -> 5200778319 | C24: 45909 | D24: =Detail!$D$58 -> Top Frame 800 | E24: 2 | G24: =Detail!$F$58 -> 225000000 | H24: =E24*G24 -> 450000000 | I24: =H24*50% -> 225000000 | J24: =(I24*20%)/E24 -> 22500000 | K24: =I24*20% -> 45000000 | M24: =SUM(K24:L24) -> 45000000 | P24: 2 | U24: =SUM(N24:S24) -> 2 | V24: =E24-U24 -> 0 | W24: =J24*U24 -> 45000000 | X24: =K24-W24 -> 0 | Y24: 45940 | Z24: =Y24+7 -> 45947 | AA24: =Z24+30 -> 45977 | AB24: =Z24+60 -> 46007 | AC24: Delivered
A25: 16 | B25: 5200778328 | C25: 45915 | D25: Top Frame 2630 | E25: 1 | G25: =Detail!F59 -> 685000000 | H25: =E25*G25 -> 685000000 | I25: =H25*50% -> 342500000 | J25: =(I25*20%)/E25 -> 68500000 | K25: =(I25*20%)+F25 -> 68500000 | L25: 66261000 | M25: =SUM(K25:L25) -> 134761000 | P25: 1 | U25: =SUM(N25:S25) -> 1 | V25: =E25-U25 -> 0 | W25: =J25*U25+L25 -> 134761000 | X25: =K25+L25-W25 -> 0 | Y25: 45940 | Z25: =Y25+7 -> 45947 | AA25: =Z25+30 -> 45977 | AB25: =Z25+60 -> 46007 | AC25: Delivered
B27: TOTAL MARGIN | I27: =SUM(I10:I26) -> 5881698600 | K27: =SUM(K10:K26) -> 1169619470 | L27: =SUM(L10:L26) -> 66261000 | M27: =SUM(M10:M26) -> 1235880470 | W27: =SUM(W10:W25) -> 1183285720 | X27: =SUM(X10:X25) -> 52594750
X28: =W27+X27-H40 -> 0
E29: A | G29: B | H29: C | I29: D | J29: E | K29: F=A+B+C-D-E
E30: TGL | F30: Modal Setor Awal | G30: Margin | H30: Pencairan Modal | I30: Modal PO Baru | J30: Penarikan Margin | K30: Dana Tersedia
E31: 45839 | F31: =SUM(I10:I12) -> 900000000 | G31: =SUM(W10:W12) -> 180000000 | K31: =F31+G31 -> 1080000000
E32: 45870 | F32: =SUM(I13:I16) -> 1125000000 | G32: =SUM(W13:W16) -> 225000000 | I32: =SUM(I17:I20) -> 1606174500 | K32: =K31+F32+G32+H32-I32-J32 -> 823825500
E33: 45901 | F33: 1426698600 | I33: =SUM(I21:I25) -> 2250524100 | K33: =K32+F33+G33+H33-I33-J33 -> 0
E34: 45931 | G34: =SUM(W17:X25) -> 830880470 | I34: =-I32-I33 -> -3856698600 | K34: =K33+F34+G34+H34-I34-J34 -> 4687579070
E35: 45962 | K35: =K34+F35+G35+H35-I35-J35 -> 4687579070
E36: 45992 | K36: =K35+F36+G36+H36-I36-J36 -> 4687579070
F37: =SUM(F31:F36) -> 3451698600 | G37: =SUM(G31:G36) -> 1235880470 | H37: =SUM(H31:H36) -> 0 | I37: =SUM(I31:I36) -> 0 | K37: =F37+G37+H37-I37 -> 4687579070
E39: Setor Modal | H39: =F37 -> 3451698600 | I39: A
E40: Margin | H40: =W27+X27 -> 1235880470 | I40: B
H41: 0
E42: Dana Tersedia | H42: =SUM(H39:H41) -> 4687579070 | I42: C=A+B
E43: Modal Yosi Ditempatkan | H43: -3000000000 | I43: D
...

Sheet Asumsi Summary V.4 (3)
B1: LIST INVESTASI
C3: Close
C4: Delivered
C5: Partial Delivery
C6: Open
C7: Margin Selisih | E7: =Detail!E2 -> 4 | G7: =Detail!F2 -> 5 | H7: =Detail!G2 -> 6 | I7: =Detail!H2 -> 7 | K7: =Detail!I2 -> 8
C8: Tidak aada di PO Tari
A10: NO | B10: No. PO | C10: Date | D10: Nama Barang | E10: =Detail!E3 -> Qty | F10: Harga Beli (only added if Margin is set) | G10: =Detail!F3 -> Harga | H10: Total PO | I10: Modal | J10: Margin Per Unit | K10: =Detail!I3 -> Margin | L10: Add Margin | M10: Total Margin | N10: Invoice /DO | U10: DO Total | V10: DO Outstanding | W10: Margin | X10: AR MARGIN | Y10: Del Time | Z10: Invoice date | AA10: Initial Payment Date | AB10: adjusting TOP 60 Days | AC10: Status | AD10: Notes | AF10: Tari | AG10: Total Margin TARI | AH10: Selisih
N11: Jul | O11: Aug | P11: Sep | Q11: Oct | R11: Nov | S11: Dec | T11: Add Margin (by Agreement) | AD11: Notes
A12: 1 | B12: 5200954145 | C12: =VLOOKUP($B12,Detail!$B$4:$Q$21,2,0) -> 45839 | D12: Top Frame 800 | E12: =SUMIF(Detail!$B$4:$B$21,'Asumsi Summary V.4 (3)'!$B12,Detail!$E$4:$E$21) -> 2 | G12: =VLOOKUP($B12,Detail!$B$4:$Q$21,5,0) -> 225000000 | H12: =E12*G12 -> 450000000 | I12: =SUMIF(Detail!$B$4:$B$21,'Asumsi Summary V.4 (3)'!B12,Detail!$H$4:$H$21) -> 225000000 | J12: =(I12*20%)/E12 -> 22500000 | K12: =I12*20% -> 45000000 | M12: =SUM(K12:L12) -> 45000000 | N12: =E12 -> 2 | U12: =SUM(N12:S12) -> 2 | V12: =E12-U12 -> 0 | W12: =J12*U12 -> 45000000 | X12: =K12-W12 -> 0 | Y12: 45861 | Z12: 45863 | AA12: 45894 | AC12: Close | AF12: =VLOOKUP(B12,investasi!$B$5:$G$18,6,0) -> 45000000 | AG12: =M12 -> 45000000 | AH12: =AF12-AG12 -> 0
A13: 2 | B13: 5200954149 | C13: =VLOOKUP($B13,Detail!$B$4:$Q$21,2,0) -> 45839 | D13: Top Frame 800 | E13: =SUMIF(Detail!$B$4:$B$21,'Asumsi Summary V.4 (3)'!$B13,Detail!$E$4:$E$21) -> 3 | G13: =VLOOKUP($B13,Detail!$B$4:$Q$21,5,0) -> 225000000 | H13: =E13*G13 -> 675000000 | I13: =SUMIF(Detail!$B$4:$B$21,'Asumsi Summary V.4 (3)'!B13,Detail!$H$4:$H$21) -> 337500000 | J13: =(I13*20%)/E13 -> 22500000 | K13: =I13*20% -> 67500000 | M13: =SUM(K13:L13) -> 67500000 | N13: =E13 -> 3 | U13: =SUM(N13:S13) -> 3 | V13: =E13-U13 -> 0 | W13: =J13*U13 -> 67500000 | X13: =K13-W13 -> 0 | Y13: 45861 | Z13: 45863 | AA13: 45894 | AC13: Close | AF13: =VLOOKUP(B13,investasi!$B$5:$G$18,6,0) -> 67500000 | AG13: =M13 -> 67500000 | AH13: =AF13-AG13 -> 0
A14: 3 | B14: 5200954160 | C14: =VLOOKUP($B14,Detail!$B$4:$Q$21,2,0) -> 45839 | D14: Top Frame 800 | E14: =SUMIF(Detail!$B$4:$B$21,'Asumsi Summary V.4 (3)'!$B14,Detail!$E$4:$E$21) -> 3 | G14: =VLOOKUP($B14,Detail!$B$4:$Q$21,5,0) -> 225000000 | H14: =E14*G14 -> 675000000 | I14: =SUMIF(Detail!$B$4:$B$21,'Asumsi Summary V.4 (3)'!B14,Detail!$H$4:$H$21) -> 337500000 | J14: =(I14*20%)/E14 -> 22500000 | K14: =I14*20% -> 67500000 | M14: =SUM(K14:L14) -> 67500000 | N14: =E14 -> 3 | U14: =SUM(N14:S14) -> 3 | V14: =E14-U14 -> 0 | W14: =J14*U14 -> 67500000 | X14: =K14-W14 -> 0 | Y14: 45861 | Z14: 45863 | AA14: 45894 | AC14: Close | AF14: =VLOOKUP(B14,investasi!$B$5:$G$18,6,0) -> 67500000 | AG14: =M14 -> 67500000 | AH14: =AF14-AG14 -> 0
A15: 4 | B15: 5200954165 | C15: =VLOOKUP($B15,Detail!$B$4:$Q$21,2,0) -> 45870 | D15: Top Frame 800 | E15: =SUMIF(Detail!$B$4:$B$21,'Asumsi Summary V.4 (3)'!$B15,Detail!$E$4:$E$21) -> 3 | G15: =VLOOKUP($B15,Detail!$B$4:$Q$21,5,0) -> 225000000 | H15: =E15*G15 -> 675000000 | I15: =SUMIF(Detail!$B$4:$B$21,'Asumsi Summary V.4 (3)'!B15,Detail!$H$4:$H$21) -> 337500000 | J15: =(I15*20%)/E15 -> 22500000 | K15: =I15*20% -> 67500000 | M15: =SUM(K15:L15) -> 67500000 | O15: =E15 -> 3 | U15: =SUM(N15:S15) -> 3 | V15: =E15-U15 -> 0 | W15: =J15*U15 -> 67500000 | X15: =K15-W15 -> 0 | Y15: 45868 | Z15: 45873 | AA15: 45904 | AC15: Close | AF15: =VLOOKUP(B15,investasi!$B$5:$G$18,6,0) -> 67500000 | AG15: =M15 -> 67500000 | AH15: =AF15-AG15 -> 0
A16: 5 | B16: 5200954167 | C16: =VLOOKUP($B16,Detail!$B$4:$Q$21,2,0) -> 45870 | D16: Top Frame 800 | E16: =SUMIF(Detail!$B$4:$B$21,'Asumsi Summary V.4 (3)'!$B16,Detail!$E$4:$E$21) -> 3 | G16: =VLOOKUP($B16,Detail!$B$4:$Q$21,5,0) -> 225000000 | H16: =E16*G16 -> 675000000 | I16: =SUMIF(Detail!$B$4:$B$21,'Asumsi Summary V.4 (3)'!B16,Detail!$H$4:$H$21) -> 337500000 | J16: =(I16*20%)/E16 -> 22500000 | K16: =I16*20% -> 67500000 | M16: =SUM(K16:L16) -> 67500000 | O16: =E16 -> 3 | U16: =SUM(N16:S16) -> 3 | V16: =E16-U16 -> 0 | W16: =J16*U16 -> 67500000 | X16: =K16-W16 -> 0 | Y16: 45868 | Z16: 45873 | AA16: 45904 | AC16: Close | AF16: =VLOOKUP(B16,investasi!$B$5:$G$18,6,0) -> 67500000 | AG16: =M16 -> 67500000 | AH16: =AF16-AG16 -> 0
A17: 6 | B17: 5200954168 | C17: =VLOOKUP($B17,Detail!$B$4:$Q$21,2,0) -> 45870 | D17: Top Frame 800 | E17: =SUMIF(Detail!$B$4:$B$21,'Asumsi Summary V.4 (3)'!$B17,Detail!$E$4:$E$21) -> 2 | G17: =VLOOKUP($B17,Detail!$B$4:$Q$21,5,0) -> 225000000 | H17: =E17*G17 -> 450000000 | I17: =SUMIF(Detail!$B$4:$B$21,'Asumsi Summary V.4 (3)'!B17,Detail!$H$4:$H$21) -> 225000000 | J17: =(I17*20%)/E17 -> 22500000 | K17: =I17*20% -> 45000000 | M17: =SUM(K17:L17) -> 45000000 | O17: =E17 -> 2 | U17: =SUM(N17:S17) -> 2 | V17: =E17-U17 -> 0 | W17: =J17*U17 -> 45000000 | X17: =K17-W17 -> 0 | Y17: 45868 | Z17: 45873 | AA17: 45904 | AC17: Close | AF17: =VLOOKUP(B17,investasi!$B$5:$G$18,6,0) -> 45000000 | AG17: =M17 -> 45000000 | AH17: =AF17-AG17 -> 0
A18: 7 | B18: 5200954169 | C18: =VLOOKUP($B18,Detail!$B$4:$Q$21,2,0) -> 45870 | D18: Top Frame 800 | E18: =SUMIF(Detail!$B$4:$B$21,'Asumsi Summary V.4 (3)'!$B18,Detail!$E$4:$E$21) -> 2 | G18: =VLOOKUP($B18,Detail!$B$4:$Q$21,5,0) -> 225000000 | H18: =E18*G18 -> 450000000 | I18: =SUMIF(Detail!$B$4:$B$21,'Asumsi Summary V.4 (3)'!B18,Detail!$H$4:$H$21) -> 225000000 | J18: =(I18*20%)/E18 -> 22500000 | K18: =I18*20% -> 45000000 | M18: =SUM(K18:L18) -> 45000000 | O18: =E18 -> 2 | U18: =SUM(N18:S18) -> 2 | V18: =E18-U18 -> 0 | W18: =J18*U18 -> 45000000 | X18: =K18-W18 -> 0 | Y18: 45868 | Z18: 45873 | AA18: 45904 | AC18: Close | AF18: =VLOOKUP(B18,investasi!$B$5:$G$18,6,0) -> 45000000 | AG18: =M18 -> 45000000 | AH18: =AF18-AG18 -> 0
A19: 8 | B19: 5200777098 | C19: =VLOOKUP($B19,Detail!$B$4:$Q$25,2,0) -> 45877 | D19: DVAR 3771-B0-20D-PPC Statcom Steel Support | E19: =SUMIF(Detail!$B$4:$B$25,'Asumsi Summary V.4 (3)'!$B19,Detail!$E$4:$E$25) -> 1 | G19: =VLOOKUP($B19,Detail!$B$4:$Q$25,5,0) -> 1149199000 | H19: =E19*G19 -> 1149199000 | I19: =SUMIF(Detail!$B$4:$B$25,'Asumsi Summary V.4 (3)'!B19,Detail!$H$4:$H$25) -> 574599500 | J19: =(I19*20%)/E19 -> 114919900 | K19: =I19*20% -> 114919900 | M19: =SUM(K19:L19) -> 114919900 | O19: 0 | P19: 1 | U19: =SUM(N19:S19) -> 1 | V19: =E19-U19 -> 0 | W19: =J19*U19 -> 114919900 | X19: =K19-W19 -> 0 | Y19: 45930 | Z19: =Y19+7 -> 45937 | AA19: =Z19+30 -> 45967 | AB19: =Z19+60 -> 45997 | AC19: Close | AF19: =VLOOKUP(B19,investasi!$B$5:$G$18,6,0) -> 57248700 | AG19: =M19 -> 114919900 | AH19: =AF19-AG19 -> -57671200 | AI19: Selisih di unit Qty, di catatan pak mushafa 2 unit(1 sudah terbayar , 1 unit belum terbayar ), dicatatan TARI 1 Unit
A20: 9 | B20: 5200776987 | C20: =VLOOKUP($B20,Detail!$B$4:$Q$25,2,0) -> 45877 | D20: Top Frame 800 | E20: =SUMIF(Detail!$B$4:$B$25,'Asumsi Summary V.4 (3)'!$B20,Detail!$E$4:$E$25) -> 2 | G20: =VLOOKUP($B20,Detail!$B$4:$Q$25,5,0) -> 225000000 | H20: =E20*G20 -> 450000000 | I20: =SUMIF(Detail!$B$4:$B$25,'Asumsi Summary V.4 (3)'!B20,Detail!$H$4:$H$25) -> 225000000 | J20: =(I20*20%)/E20 -> 22500000 | K20: =I20*20% -> 45000000 | M20: =SUM(K20:L20) -> 45000000 | O20: 0 | P20: 2 | U20: =SUM(N20:S20) -> 2 | V20: =E20-U20 -> 0 | W20: =J20*U20 -> 45000000 | X20: =K20-W20 -> 0 | Y20: 45923 | Z20: =Y20+7 -> 45930 | AA20: =Z20+30 -> 45960 | AB20: =Z20+60 -> 45990 | AC20: Close | AF20: =VLOOKUP(B20,investasi!$B$5:$G$18,6,0) -> 45000000 | AG20: =M20 -> 45000000 | AH20: =AF20-AG20 -> 0
A21: 10 | B21: 5200777132 | C21: =VLOOKUP($B21,Detail!$B$4:$Q$110,2,0) -> 45880 | D21: Leser Barrier MK 01-F3004973 | E21: 20 | G21: =VLOOKUP($B21,Detail!$B$4:$Q$25,5,0) -> 40457500 | H21: =E21*G21 -> 809150000 | I21: =H21*50% -> 404575000 | J21: =(I21*13%)/E21 -> 2629737.5 | K21: =I21*13% -> 52594750 | M21: =SUM(K21:L21) -> 52594750 | O21: 0 | Q21: 20 | U21: =SUM(N21:S21) -> 20 | V21: =E21-U21 -> 0 | W21: =J21*U21 -> 52594750 | X21: =K21-W21 -> 0 | Y21: 45922 | Z21: =Y21+7 -> 45929 | AA21: =Z21+30 -> 45959 | AB21: =Z21+60 -> 45989 | AC21: Close | AF21: =VLOOKUP(B21,investasi!$B$5:$G$18,6,0) -> 52594750 | AG21: =M21 -> 52594750 | AH21: =AF21-AG21 -> 0
A22: 11 | B22: =Detail!$B$45 -> 5200972695 | C22: =Detail!$C$45 -> 45891 | D22: Tangki | E22: 8 | F22: 75000000 | G22: 100500000 | H22: =E22*G22 -> 804000000 | I22: =H22*50% -> 402000000 | J22: 12750000 | K22: =E22*J22 -> 102000000 | M22: =SUM(K22:L22) -> 102000000 | O22: 0 | P22: 8 | T22: Margin was arranged 25mil/ea | U22: =SUM(N22:S22) -> 8 | V22: =E22-U22 -> 0 | W22: =J22*U22 -> 102000000 | X22: =K22-W22 -> 0 | Y22: 45925 | Z22: =Y22+7 -> 45932 | AA22: =Z22+30 -> 45962 | AB22: =Z22+60 -> 45992 | AC22: Close | AF22: =VLOOKUP(B22,investasi!$B$5:$G$18,6,0) -> 80400000 | AG22: =M22 -> 102000000 | AH22: =AF22-AG22 -> -21600000 | AI22: Selisih margin
A23: 12 | B23: =Detail!B53 -> 5200777558 | C23: 45897 | D23: Top Frame 2630 | E23: 1 | G23: =Detail!F53 -> 685000000 | H23: =E23*G23 -> 685000000 | I23: =H23*50% -> 342500000 | J23: =(I23*20%)/E23 -> 68500000 | K23: =I23*20% -> 68500000 | M23: =SUM(K23:L23) -> 68500000 | P23: 1 | U23: =SUM(N23:S23) -> 1 | V23: =E23-U23 -> 0 | W23: =J23*U23 -> 68500000 | X23: =K23-W23 -> 0 | Y23: 45923 | Z23: =Y23+7 -> 45930 | AA23: =Z23+30 -> 45960 | AB23: =Z23+60 -> 45990 | AC23: Close | AF23: =VLOOKUP(B23,investasi!$B$5:$G$18,6,0) -> 68500000 | AG23: =M23 -> 68500000 | AH23: =AF23-AG23 -> 0
A24: 13 | B24: =Detail!B54 -> 5200777559 | C24: 45901 | D24: Top Frame 800 | E24: 2 | G24: =Detail!F54 -> 225000000 | H24: =E24*G24 -> 450000000 | I24: =H24*50% -> 225000000 | J24: =(I24*20%)/E24 -> 22500000 | K24: =I24*20% -> 45000000 | M24: =SUM(K24:L24) -> 45000000 | P24: 2 | U24: =SUM(N24:S24) -> 2 | V24: =E24-U24 -> 0 | W24: =J24*U24 -> 45000000 | X24: =K24-W24 -> 0 | Y24: 45925 | Z24: =Y24+7 -> 45932 | AA24: =Z24+30 -> 45962 | AB24: =Z24+60 -> 45992 | AC24: Close | AF24: =VLOOKUP(B24,investasi!$B$5:$G$18,6,0) -> 45000000 | AG24: =M24 -> 45000000 | AH24: =AF24-AG24 -> 0
A25: 14 | B25: =Detail!$B$56 -> 5200777758 | C25: 45909 | D25: Pipe Spool | E25: 1 | G25: =Detail!F56 -> 2231048200 | H25: =E25*G25 -> 2231048200 | I25: =H25*50% -> 1115524100 | J25: =(I25*20%)/E25 -> 223104820 | K25: =I25*20% -> 223104820 | M25: =SUM(K25:L25) -> 223104820 | P25: 1 | U25: =SUM(N25:S25) -> 1 | V25: =E25-U25 -> 0 | W25: =J25*U25 -> 223104820 | X25: =K25-W25 -> 0 | Y25: 45930 | Z25: =Y25+7 -> 45937 | AA25: =Z25+30 -> 45967 | AB25: =Z25+60 -> 45997 | AC25: Close | AF25: =VLOOKUP(B25,investasi!$B$5:$G$18,6,0) -> 223104820 | AG25: =M25 -> 223104820 | AH25: =AF25-AG25 -> 0
A26: 15 | B26: =Detail!$B$58 -> 5200778319 | C26: 45909 | D26: =Detail!$D$58 -> Top Frame 800 | E26: 2 | G26: =Detail!$F$58 -> 225000000 | H26: =E26*G26 -> 450000000 | I26: =H26*50% -> 225000000 | J26: =(I26*20%)/E26 -> 22500000 | K26: =I26*20% -> 45000000 | M26: =SUM(K26:L26) -> 45000000 | P26: 2 | U26: =SUM(N26:S26) -> 2 | V26: =E26-U26 -> 0 | W26: =J26*U26 -> 45000000 | X26: =K26-W26 -> 0 | Y26: 45940 | Z26: =Y26+7 -> 45947 | AA26: =Z26+30 -> 45977 | AB26: =Z26+60 -> 46007 | AC26: Close | AF26: =VLOOKUP(B26,investasi!$B$23:$G$26,6,0) -> 45000000 | AG26: =M26 -> 45000000 | AH26: =AF26-AG26 -> 0
A27: 16 | B27: 5200778328 | C27: 45915 | D27: Top Frame 2630 | E27: 1 | G27: =Detail!F59 -> 685000000 | H27: =E27*G27 -> 685000000 | I27: =H27*50% -> 342500000 | J27: =(I27*20%)/E27 -> 68500000 | K27: =(I27*20%)+F27 -> 68500000 | L27: 66261000 | M27: =SUM(K27:L27) -> 134761000 | P27: 1 | U27: =SUM(N27:S27) -> 1 | V27: =E27-U27 -> 0 | W27: =J27*U27+L27 -> 134761000 | X27: =K27+L27-W27 -> 0 | Y27: 45940 | Z27: =Y27+7 -> 45947 | AA27: =Z27+30 -> 45977 | AB27: =Z27+60 -> 46007 | AC27: Close | AF27: =VLOOKUP(B27,investasi!$B$23:$G$26,6,0)+investasi!I24 -> 134761000 | AG27: =M27 -> 134761000 | AH27: =AF27-AG27 -> 0
U28: =SUM(N28:S28) -> 0 | AC28: Close
A29: 18 | B29: =Detail!B60 -> 5200779815 | C29: 45965 | D29: Top Frame 2630 | E29: 1 | G29: =Detail!F60 -> 685000000 | H29: =E29*G29 -> 685000000 | I29: =H29*50% -> 342500000 | J29: =(I29*20%)/E29 -> 68500000 | K29: =(I29*20%)+F29 -> 68500000 | L29: 66261000 | M29: =SUM(K29:L29) -> 134761000 | R29: 1 | U29: =SUM(N29:S29) -> 1 | V29: =E29-U29 -> 0 | W29: =J29*U29+L29 -> 134761000 | X29: =K29+L29-W29 -> 0 | Y29: 45989 | Z29: =Y29+3 -> 45992 | AA29: =Z29+30 -> 46022 | AB29: =Z29+60 -> 46052 | AC29: Delivered | AF29: =VLOOKUP(B29,investasi!$B$23:$G$26,6,0)+investasi!I26 -> 134761000 | AG29: =M29 -> 134761000 | AH29: =AF29-AG29 -> 0
A30: =A29+1 -> 19 | B30: 5200988854 | C30: 45977 | D30: Trench Grade | E30: 150 | G30: 4990500 | H30: =E30*G30 -> 748575000 | I30: =H30*50% -> 374287500 | J30: =(I30*20%)/E30 -> 499050 | K30: =(I30*20%)+F30 -> 74857500 | M30: =SUM(K30:L30) -> 74857500 | R30: 150 | U30: =SUM(N30:S30) -> 150 | V30: =E30-U30 -> 0 | W30: =J30*U30+L30 -> 74857500 | X30: =K30+L30-W30 -> 0 | Y30: 45989 | Z30: =Y30+3 -> 45992 | AA30: =Z30+30 -> 46022 | AB30: =Z30+60 -> 46052 | AC30: Delivered
A31: =A30+1 -> 20 | B31: 5200989664 | C31: 45977 | D31: Grating Ditch | E31: 100 | G31: 21100000 | H31: =E31*G31 -> 2110000000 | I31: =H31*50% -> 1055000000 | J31: =(I31*20%)/E31 -> 2110000 | K31: =(I31*20%)+F31 -> 211000000 | M31: =SUM(K31:L31) -> 211000000 | U31: =SUM(N31:S31) -> 0 | X31: =K31+L31-W31 -> 211000000 | AC31: Open
A32: =A31+1 -> 21 | B32: 5200989665 | C32: 45977 | D32: Grating Ditch | E32: 100 | G32: 21100000 | H32: =E32*G32 -> 2110000000 | I32: =H32*50% -> 1055000000 | J32: =(I32*20%)/E32 -> 2110000 | K32: =(I32*20%)+F32 -> 211000000 | M32: =SUM(K32:L32) -> 211000000 | U32: =SUM(N32:S32) -> 0 | X32: =K32+L32-W32 -> 211000000 | AC32: Open
A33: =A32+1 -> 22 | B33: 5200989666 | C33: 45977 | D33: Grating Ditch | E33: 110 | G33: 21100000 | H33: =E33*G33 -> 2321000000 | I33: =H33*50% -> 1160500000 | J33: =(I33*20%)/E33 -> 2110000 | K33: =(I33*20%)+F33 -> 232100000 | M33: =SUM(K33:L33) -> 232100000 | U33: =SUM(N33:S33) -> 0 | X33: =K33+L33-W33 -> 232100000 | AC33: Open
A34: =A33+1 -> 23 | B34: 5200992759 | C34: 45981 | D34: Tanki | E34: 6 | G34: 100500000 | H34: =E34*G34 -> 603000000 | I34: =H34*50% -> 301500000 | J34: 12750000 | K34: =J34*E34 -> 76500000 | M34: =SUM(K34:L34) -> 76500000 | U34: =SUM(N34:S34) -> 0 | X34: =K34+L34-W34 -> 76500000 | AC34: Open
A35: =A34+1 -> 24 | B35: 5200991260 | C35: 45985 | D35: Trench Grade | E35: 150 | G35: 4990500 | H35: =E35*G35 -> 748575000 | I35: =H35*50% -> 374287500 | J35: =(I35*20%)/E35 -> 499050 | K35: =(I35*20%)+F35 -> 74857500 | M35: =SUM(K35:L35) -> 74857500 | U35: =SUM(N35:S35) -> 0 | X35: =K35+L35-W35 -> 74857500 | Y35: =C35+14 -> 45999 | Z35: =Y35+7 -> 46006 | AA35: =Z35+30 -> 46036 | AB35: =Z35+60 -> 46066 | AC35: Open
A36: =A35+1 -> 25 | B36: 5200991264 | C36: 45985 | D36: Trench Grade | E36: 150 | G36: 4990500 | H36: =E36*G36 -> 748575000 | I36: =H36*50% -> 374287500 | J36: =(I36*20%)/E36 -> 499050 | K36: =(I36*20%)+F36 -> 74857500 | M36: =SUM(K36:L36) -> 74857500 | U36: =SUM(N36:S36) -> 0 | X36: =K36+L36-W36 -> 74857500 | Y36: =C36+21 -> 46006 | Z36: =Y36+7 -> 46013 | AA36: =Z36+30 -> 46043 | AB36: =Z36+60 -> 46073 | AC36: Open
A37: =A36+1 -> 26 | B37: 5200991456 | C37: 45986 | D37: Trench Grade | E37: 150 | G37: 4990500 | H37: =E37*G37 -> 748575000 | I37: =H37*50% -> 374287500 | J37: =(I37*20%)/E37 -> 499050 | K37: =(I37*20%)+F37 -> 74857500 | M37: =SUM(K37:L37) -> 74857500 | U37: =SUM(N37:S37) -> 0 | X37: =K37+L37-W37 -> 74857500 | Y37: =C37+21 -> 46007 | Z37: =Y37+7 -> 46014 | AA37: =Z37+30 -> 46044 | AB37: =Z37+60 -> 46074 | AC37: Open
A38: =A37+1 -> 27 | B38: 5200991458 | C38: 45986 | D38: Trench Grade | E38: 150 | G38: 4990500 | H38: =E38*G38 -> 748575000 | I38: =H38*50% -> 374287500 | J38: =(I38*20%)/E38 -> 499050 | K38: =(I38*20%)+F38 -> 74857500 | M38: =SUM(K38:L38) -> 74857500 | U38: =SUM(N38:S38) -> 0 | X38: =K38+L38-W38 -> 74857500 | Y38: =C38+21 -> 46007 | Z38: =Y38+7 -> 46014 | AA38: =Z38+30 -> 46044 | AB38: =Z38+60 -> 46074 | AC38: Open
A39: =A38+1 -> 28 | B39: 5200991502 | C39: 45986 | D39: Trench Grade | E39: 150 | G39: 4990500 | H39: =E39*G39 -> 748575000 | I39: =H39*50% -> 374287500 | J39: =(I39*20%)/E39 -> 499050 | K39: =(I39*20%)+F39 -> 74857500 | M39: =SUM(K39:L39) -> 74857500 | U39: =SUM(N39:S39) -> 0 | X39: =K39+L39-W39 -> 74857500 | Y39: =C39+21 -> 46007 | Z39: =Y39+7 -> 46014 | AA39: =Z39+30 -> 46044 | AB39: =Z39+60 -> 46074 | AC39: Open
A40: =A39+1 -> 29 | B40: 5200991502 | C40: 45986 | D40: Trench Grade | E40: 150 | G40: 4990500 | H40: =E40*G40 -> 748575000 | I40: =H40*50% -> 374287500 | J40: =(I40*20%)/E40 -> 499050 | K40: =(I40*20%)+F40 -> 74857500 | M40: =SUM(K40:L40) -> 74857500 | U40: =SUM(N40:S40) -> 0 | X40: =K40+L40-W40 -> 74857500 | Y40: =C40+21 -> 46007 | Z40: =Y40+7 -> 46014 | AA40: =Z40+30 -> 46044 | AB40: =Z40+60 -> 46074 | AC40: Open
A41: =A40+1 -> 30 | B41: 5200991502 | C41: 45986 | D41: Trench Grade | E41: 50 | G41: 4990500 | H41: =E41*G41 -> 249525000 | I41: =H41*50% -> 124762500 | J41: =(I41*20%)/E41 -> 499050 | K41: =(I41*20%)+F41 -> 24952500 | M41: =SUM(K41:L41) -> 24952500 | U41: =SUM(N41:S41) -> 0 | X41: =K41+L41-W41 -> 24952500 | Y41: =C41+21 -> 46007 | Z41: =Y41+7 -> 46014 | AA41: =Z41+30 -> 46044 | AB41: =Z41+60 -> 46074 | AC41: Open
B43: TOTAL MARGIN | H43: =SUM(H12:H41) -> 25081947200 | I43: =SUM(I12:I41) -> 12540973600 | K43: =SUM(K12:K41) -> 2517674470 | L43: =SUM(L12:L34) -> 132522000 | M43: =SUM(M12:M41) -> 2650196470 | W43: =SUM(W12:W40) -> 1445498970 | X43: =SUM(X12:X40) -> 1179745000
...

Sheet Summary V.4 (6)
C1: LIST INVESTASI
H7: =Detail!E2 -> 4 | J7: =Detail!F2 -> 5 | K7: =Detail!G2 -> 6 | L7: =Detail!H2 -> 7 | N7: =Detail!I2 -> 8
A10: NO | B10: Date | C10: No. PO | D10: Status | E10: Margin Diterima | F10: Modal Di terima | G10: Nama Barang | H10: =Detail!E3 -> Qty | I10: Harga Beli (only added if Margin is set) | J10: =Detail!F3 -> Harga | K10: Total PO | L10: Modal | M10: Margin Per Unit | N10: =Detail!I3 -> Margin | O10: Add Margin | P10: Total Margin | Q10: Invoice /DO | Y10: DO Total | Z10: DO Outstanding | AA10: Margin | AB10: Margin ditahan | AC10: MODAL DITAHAN | AD10: Del Time | AE10: Invoice date | AF10: adjusting TOP 30 Days | AG10: adjusting TOP 60 Days | AH10: Payment Date | AI10: Status | AJ10: Notes | AK10: Tari | AL10: Total Margin TARI | AM10: Selisih
Q11: Jul | R11: Aug | S11: Sep | T11: Oct | U11: Nov | V11: Dec | W11: Jan | X11: Add Margin (by Agreement) | AJ11: Notes
A12: 1 | B12: =VLOOKUP($C12,Detail!$B$4:$Q$21,2,0) -> 45839 | C12: 5200954145 | D12: Close | E12: =P12-AB12 -> 45000000 | F12: =L12-AC12 -> 225000000 | G12: Top Frame 800 | H12: =SUMIF(Detail!$B$4:$B$21,'Summary V.4 (6)'!$C12,Detail!$E$4:$E$21) -> 2 | J12: =VLOOKUP($C12,Detail!$B$4:$Q$21,5,0) -> 225000000 | K12: =H12*J12 -> 450000000 | L12: =SUMIF(Detail!$B$4:$B$21,'Summary V.4 (6)'!C12,Detail!$H$4:$H$21) -> 225000000 | M12: =(L12*20%)/H12 -> 22500000 | N12: =L12*20% -> 45000000 | P12: =SUM(N12:O12) -> 45000000 | Q12: =H12 -> 2 | Y12: =SUM(Q12:V12) -> 2 | Z12: =H12-Y12 -> 0 | AA12: =P12 -> 45000000 | AB12: =N12-AA12 -> 0 | AD12: 45861 | AE12: 45863 | AF12: 45894 | AI12: Close | AK12: =VLOOKUP(C12,investasi!$B$5:$G$18,6,0) -> 45000000 | AL12: =P12 -> 45000000 | AM12: =AK12-AL12 -> 0
A13: 2 | B13: =VLOOKUP($C13,Detail!$B$4:$Q$21,2,0) -> 45839 | C13: 5200954149 | D13: Close | E13: =P13-AB13 -> 67500000 | F13: =L13-AC13 -> 337500000 | G13: Top Frame 800 | H13: =SUMIF(Detail!$B$4:$B$21,'Summary V.4 (6)'!$C13,Detail!$E$4:$E$21) -> 3 | J13: =VLOOKUP($C13,Detail!$B$4:$Q$21,5,0) -> 225000000 | K13: =H13*J13 -> 675000000 | L13: =SUMIF(Detail!$B$4:$B$21,'Summary V.4 (6)'!C13,Detail!$H$4:$H$21) -> 337500000 | M13: =(L13*20%)/H13 -> 22500000 | N13: =L13*20% -> 67500000 | P13: =SUM(N13:O13) -> 67500000 | Q13: =H13 -> 3 | Y13: =SUM(Q13:V13) -> 3 | Z13: =H13-Y13 -> 0 | AA13: =P13 -> 67500000 | AB13: =N13-AA13 -> 0 | AD13: 45861 | AE13: 45863 | AF13: 45894 | AI13: Close | AK13: =VLOOKUP(C13,investasi!$B$5:$G$18,6,0) -> 67500000 | AL13: =P13 -> 67500000 | AM13: =AK13-AL13 -> 0
A14: 3 | B14: =VLOOKUP($C14,Detail!$B$4:$Q$21,2,0) -> 45839 | C14: 5200954160 | D14: Close | E14: =P14-AB14 -> 67500000 | F14: =L14-AC14 -> 337500000 | G14: Top Frame 800 | H14: =SUMIF(Detail!$B$4:$B$21,'Summary V.4 (6)'!$C14,Detail!$E$4:$E$21) -> 3 | J14: =VLOOKUP($C14,Detail!$B$4:$Q$21,5,0) -> 225000000 | K14: =H14*J14 -> 675000000 | L14: =SUMIF(Detail!$B$4:$B$21,'Summary V.4 (6)'!C14,Detail!$H$4:$H$21) -> 337500000 | M14: =(L14*20%)/H14 -> 22500000 | N14: =L14*20% -> 67500000 | P14: =SUM(N14:O14) -> 67500000 | Q14: =H14 -> 3 | Y14: =SUM(Q14:V14) -> 3 | Z14: =H14-Y14 -> 0 | AA14: =P14 -> 67500000 | AB14: =N14-AA14 -> 0 | AD14: 45861 | AE14: 45863 | AF14: 45894 | AI14: Close | AK14: =VLOOKUP(C14,investasi!$B$5:$G$18,6,0) -> 67500000 | AL14: =P14 -> 67500000 | AM14: =AK14-AL14 -> 0
A15: 4 | B15: =VLOOKUP($C15,Detail!$B$4:$Q$21,2,0) -> 45870 | C15: 5200954165 | D15: Close | E15: =P15-AB15 -> 67500000 | F15: =L15-AC15 -> 337500000 | G15: Top Frame 800 | H15: =SUMIF(Detail!$B$4:$B$21,'Summary V.4 (6)'!$C15,Detail!$E$4:$E$21) -> 3 | J15: =VLOOKUP($C15,Detail!$B$4:$Q$21,5,0) -> 225000000 | K15: =H15*J15 -> 675000000 | L15: =SUMIF(Detail!$B$4:$B$21,'Summary V.4 (6)'!C15,Detail!$H$4:$H$21) -> 337500000 | M15: =(L15*20%)/H15 -> 22500000 | N15: =L15*20% -> 67500000 | P15: =SUM(N15:O15) -> 67500000 | R15: =H15 -> 3 | Y15: =SUM(Q15:V15) -> 3 | Z15: =H15-Y15 -> 0 | AA15: =P15 -> 67500000 | AB15: =N15-AA15 -> 0 | AD15: 45868 | AE15: 45873 | AF15: 45904 | AI15: Close | AK15: =VLOOKUP(C15,investasi!$B$5:$G$18,6,0) -> 67500000 | AL15: =P15 -> 67500000 | AM15: =AK15-AL15 -> 0
A16: 5 | B16: =VLOOKUP($C16,Detail!$B$4:$Q$21,2,0) -> 45870 | C16: 5200954167 | D16: Close | E16: =P16-AB16 -> 67500000 | F16: =L16-AC16 -> 337500000 | G16: Top Frame 800 | H16: =SUMIF(Detail!$B$4:$B$21,'Summary V.4 (6)'!$C16,Detail!$E$4:$E$21) -> 3 | J16: =VLOOKUP($C16,Detail!$B$4:$Q$21,5,0) -> 225000000 | K16: =H16*J16 -> 675000000 | L16: =SUMIF(Detail!$B$4:$B$21,'Summary V.4 (6)'!C16,Detail!$H$4:$H$21) -> 337500000 | M16: =(L16*20%)/H16 -> 22500000 | N16: =L16*20% -> 67500000 | P16: =SUM(N16:O16) -> 67500000 | R16: =H16 -> 3 | Y16: =SUM(Q16:V16) -> 3 | Z16: =H16-Y16 -> 0 | AA16: =P16 -> 67500000 | AB16: =N16-AA16 -> 0 | AD16: 45868 | AE16: 45873 | AF16: 45904 | AI16: Close | AK16: =VLOOKUP(C16,investasi!$B$5:$G$18,6,0) -> 67500000 | AL16: =P16 -> 67500000 | AM16: =AK16-AL16 -> 0
A17: 6 | B17: =VLOOKUP($C17,Detail!$B$4:$Q$21,2,0) -> 45870 | C17: 5200954168 | D17: Close | E17: =P17-AB17 -> 45000000 | F17: =L17-AC17 -> 225000000 | G17: Top Frame 800 | H17: =SUMIF(Detail!$B$4:$B$21,'Summary V.4 (6)'!$C17,Detail!$E$4:$E$21) -> 2 | J17: =VLOOKUP($C17,Detail!$B$4:$Q$21,5,0) -> 225000000 | K17: =H17*J17 -> 450000000 | L17: =SUMIF(Detail!$B$4:$B$21,'Summary V.4 (6)'!C17,Detail!$H$4:$H$21) -> 225000000 | M17: =(L17*20%)/H17 -> 22500000 | N17: =L17*20% -> 45000000 | P17: =SUM(N17:O17) -> 45000000 | R17: =H17 -> 2 | Y17: =SUM(Q17:V17) -> 2 | Z17: =H17-Y17 -> 0 | AA17: =P17 -> 45000000 | AB17: =N17-AA17 -> 0 | AD17: 45868 | AE17: 45873 | AF17: 45904 | AI17: Close | AK17: =VLOOKUP(C17,investasi!$B$5:$G$18,6,0) -> 45000000 | AL17: =P17 -> 45000000 | AM17: =AK17-AL17 -> 0
A18: 7 | B18: =VLOOKUP($C18,Detail!$B$4:$Q$21,2,0) -> 45870 | C18: 5200954169 | D18: Close | E18: =P18-AB18 -> 45000000 | F18: =L18-AC18 -> 225000000 | G18: Top Frame 800 | H18: =SUMIF(Detail!$B$4:$B$21,'Summary V.4 (6)'!$C18,Detail!$E$4:$E$21) -> 2 | J18: =VLOOKUP($C18,Detail!$B$4:$Q$21,5,0) -> 225000000 | K18: =H18*J18 -> 450000000 | L18: =SUMIF(Detail!$B$4:$B$21,'Summary V.4 (6)'!C18,Detail!$H$4:$H$21) -> 225000000 | M18: =(L18*20%)/H18 -> 22500000 | N18: =L18*20% -> 45000000 | P18: =SUM(N18:O18) -> 45000000 | R18: =H18 -> 2 | Y18: =SUM(Q18:V18) -> 2 | Z18: =H18-Y18 -> 0 | AA18: =P18 -> 45000000 | AB18: =N18-AA18 -> 0 | AD18: 45868 | AE18: 45873 | AF18: 45904 | AI18: Close | AK18: =VLOOKUP(C18,investasi!$B$5:$G$18,6,0) -> 45000000 | AL18: =P18 -> 45000000 | AM18: =AK18-AL18 -> 0
A19: 8 | B19: =VLOOKUP($C19,Detail!$B$4:$Q$25,2,0) -> 45877 | C19: 5200777098 | D19: Close | E19: =P19-AB19 -> 114919900 | F19: =L19-AC19 -> 574599500 | G19: DVAR 3771-B0-20D-PPC Statcom Steel Support | H19: =SUMIF(Detail!$B$4:$B$25,'Summary V.4 (6)'!$C19,Detail!$E$4:$E$25) -> 1 | J19: =VLOOKUP($C19,Detail!$B$4:$Q$25,5,0) -> 1149199000 | K19: =H19*J19 -> 1149199000 | L19: =SUMIF(Detail!$B$4:$B$25,'Summary V.4 (6)'!C19,Detail!$H$4:$H$25) -> 574599500 | M19: =(L19*20%)/H19 -> 114919900 | N19: =L19*20% -> 114919900 | P19: =SUM(N19:O19) -> 114919900 | R19: 0 | S19: 1 | Y19: =SUM(Q19:V19) -> 1 | Z19: =H19-Y19 -> 0 | AA19: =P19 -> 114919900 | AB19: =N19-AA19 -> 0 | AD19: 45930 | AE19: =AD19+7 -> 45937 | AF19: =AE19+30 -> 45967 | AG19: =AE19+60 -> 45997 | AI19: Close | AK19: =VLOOKUP(C19,investasi!$B$5:$G$18,6,0) -> 57248700 | AL19: =P19 -> 114919900 | AM19: =AK19-AL19 -> -57671200 | AN19: Selisih di unit Qty, di catatan pak mushafa 2 unit(1 sudah terbayar , 1 unit belum terbayar ), dicatatan TARI 1 Unit
A20: 9 | B20: =VLOOKUP($C20,Detail!$B$4:$Q$25,2,0) -> 45877 | C20: 5200776987 | D20: Close | E20: =P20-AB20 -> 45000000 | F20: =L20-AC20 -> 225000000 | G20: Top Frame 800 | H20: =SUMIF(Detail!$B$4:$B$25,'Summary V.4 (6)'!$C20,Detail!$E$4:$E$25) -> 2 | J20: =VLOOKUP($C20,Detail!$B$4:$Q$25,5,0) -> 225000000 | K20: =H20*J20 -> 450000000 | L20: =SUMIF(Detail!$B$4:$B$25,'Summary V.4 (6)'!C20,Detail!$H$4:$H$25) -> 225000000 | M20: =(L20*20%)/H20 -> 22500000 | N20: =L20*20% -> 45000000 | P20: =SUM(N20:O20) -> 45000000 | R20: 0 | S20: 2 | Y20: =SUM(Q20:V20) -> 2 | Z20: =H20-Y20 -> 0 | AA20: =P20 -> 45000000 | AB20: =N20-AA20 -> 0 | AD20: 45923 | AE20: =AD20+7 -> 45930 | AF20: =AE20+30 -> 45960 | AG20: =AE20+60 -> 45990 | AI20: Close | AK20: =VLOOKUP(C20,investasi!$B$5:$G$18,6,0) -> 45000000 | AL20: =P20 -> 45000000 | AM20: =AK20-AL20 -> 0
A21: 10 | B21: =VLOOKUP($C21,Detail!$B$4:$Q$110,2,0) -> 45880 | C21: 5200777132 | D21: Close | E21: =P21-AB21 -> 52594750 | F21: =L21-AC21 -> 404575000 | G21: Leser Barrier MK 01-F3004973 | H21: 20 | J21: =VLOOKUP($C21,Detail!$B$4:$Q$25,5,0) -> 40457500 | K21: =H21*J21 -> 809150000 | L21: =K21*50% -> 404575000 | M21: =(L21*13%)/H21 -> 2629737.5 | N21: =L21*13% -> 52594750 | P21: =SUM(N21:O21) -> 52594750 | R21: 0 | T21: 20 | Y21: =SUM(Q21:V21) -> 20 | Z21: =H21-Y21 -> 0 | AA21: =P21 -> 52594750 | AB21: =N21-AA21 -> 0 | AD21: 45922 | AE21: =AD21+7 -> 45929 | AF21: =AE21+30 -> 45959 | AG21: =AE21+60 -> 45989 | AI21: Close | AK21: =VLOOKUP(C21,investasi!$B$5:$G$18,6,0) -> 52594750 | AL21: =P21 -> 52594750 | AM21: =AK21-AL21 -> 0
A22: 11 | B22: =Detail!$C$45 -> 45891 | C22: =Detail!$B$45 -> 5200972695 | D22: Close | E22: =P22-AB22 -> 102000000 | F22: =L22-AC22 -> 402000000 | G22: Tangki | H22: 8 | I22: 75000000 | J22: 100500000 | K22: =H22*J22 -> 804000000 | L22: =K22*50% -> 402000000 | M22: 12750000 | N22: =H22*M22 -> 102000000 | P22: =SUM(N22:O22) -> 102000000 | R22: 0 | S22: 8 | X22: Margin was arranged 25mil/ea | Y22: =SUM(Q22:V22) -> 8 | Z22: =H22-Y22 -> 0 | AA22: =P22 -> 102000000 | AB22: =N22-AA22 -> 0 | AD22: 45925 | AE22: =AD22+7 -> 45932 | AF22: =AE22+30 -> 45962 | AG22: =AE22+60 -> 45992 | AI22: Close | AK22: =VLOOKUP(C22,investasi!$B$5:$G$18,6,0) -> 80400000 | AL22: =P22 -> 102000000 | AM22: =AK22-AL22 -> -21600000 | AN22: Selisih margin | AP22: 21600000
A23: 12 | B23: 45897 | C23: =Detail!B53 -> 5200777558 | D23: Close | E23: =P23-AB23 -> 68500000 | F23: =L23-AC23 -> 342500000 | G23: Top Frame 2630 | H23: 1 | J23: =Detail!F53 -> 685000000 | K23: =H23*J23 -> 685000000 | L23: =K23*50% -> 342500000 | M23: =(L23*20%)/H23 -> 68500000 | N23: =L23*20% -> 68500000 | P23: =SUM(N23:O23) -> 68500000 | S23: 1 | Y23: =SUM(Q23:V23) -> 1 | Z23: =H23-Y23 -> 0 | AA23: =P23 -> 68500000 | AB23: =N23-AA23 -> 0 | AD23: 45923 | AE23: =AD23+7 -> 45930 | AF23: =AE23+30 -> 45960 | AG23: =AE23+60 -> 45990 | AI23: Close | AK23: =VLOOKUP(C23,investasi!$B$5:$G$18,6,0) -> 68500000 | AL23: =P23 -> 68500000 | AM23: =AK23-AL23 -> 0
A24: 13 | B24: 45901 | C24: =Detail!B54 -> 5200777559 | D24: Close | E24: =P24-AB24 -> 45000000 | F24: =L24-AC24 -> 225000000 | G24: Top Frame 800 | H24: 2 | J24: =Detail!F54 -> 225000000 | K24: =H24*J24 -> 450000000 | L24: =K24*50% -> 225000000 | M24: =(L24*20%)/H24 -> 22500000 | N24: =L24*20% -> 45000000 | P24: =SUM(N24:O24) -> 45000000 | S24: 2 | Y24: =SUM(Q24:V24) -> 2 | Z24: =H24-Y24 -> 0 | AA24: =P24 -> 45000000 | AB24: =N24-AA24 -> 0 | AD24: 45925 | AE24: =AD24+7 -> 45932 | AF24: =AE24+30 -> 45962 | AG24: =AE24+60 -> 45992 | AI24: Close | AK24: =VLOOKUP(C24,investasi!$B$5:$G$18,6,0) -> 45000000 | AL24: =P24 -> 45000000 | AM24: =AK24-AL24 -> 0
A25: 14 | B25: 45909 | C25: =Detail!$B$56 -> 5200777758 | D25: Close | E25: =P25-AB25 -> 223104820 | F25: =L25-AC25 -> 1115524100 | G25: Pipe Spool | H25: 1 | J25: =Detail!F56 -> 2231048200 | K25: =H25*J25 -> 2231048200 | L25: =K25*50% -> 1115524100 | M25: =(L25*20%)/H25 -> 223104820 | N25: =L25*20% -> 223104820 | P25: =SUM(N25:O25) -> 223104820 | S25: 1 | Y25: =SUM(Q25:V25) -> 1 | Z25: =H25-Y25 -> 0 | AA25: =P25 -> 223104820 | AB25: =N25-AA25 -> 0 | AD25: 45930 | AE25: =AD25+7 -> 45937 | AF25: =AE25+30 -> 45967 | AG25: =AE25+60 -> 45997 | AI25: Close | AK25: =VLOOKUP(C25,investasi!$B$5:$G$18,6,0) -> 223104820 | AL25: =P25 -> 223104820 | AM25: =AK25-AL25 -> 0
A26: 15 | B26: 45909 | C26: =Detail!$B$58 -> 5200778319 | D26: Close | E26: =P26-AB26 -> 45000000 | F26: =L26-AC26 -> 225000000 | G26: =Detail!$D$58 -> Top Frame 800 | H26: 2 | J26: =Detail!$F$58 -> 225000000 | K26: =H26*J26 -> 450000000 | L26: =K26*50% -> 225000000 | M26: =(L26*20%)/H26 -> 22500000 | N26: =L26*20% -> 45000000 | P26: =SUM(N26:O26) -> 45000000 | S26: 2 | Y26: =SUM(Q26:V26) -> 2 | Z26: =H26-Y26 -> 0 | AA26: =P26 -> 45000000 | AB26: =N26-AA26 -> 0 | AD26: 45940 | AE26: =AD26+7 -> 45947 | AF26: =AE26+30 -> 45977 | AG26: =AE26+60 -> 46007 | AI26: Close | AK26: =VLOOKUP(C26,investasi!$B$23:$G$26,6,0) -> 45000000 | AL26: =P26 -> 45000000 | AM26: =AK26-AL26 -> 0
A27: 16 | B27: 45915 | C27: 5200778328 | D27: Close | E27: =P27-AB27 -> 134761000 | F27: =L27-AC27 -> 342500000 | G27: Top Frame 2630 | H27: 1 | J27: =Detail!F59 -> 685000000 | K27: =H27*J27 -> 685000000 | L27: =K27*50% -> 342500000 | M27: =(L27*20%)/H27 -> 68500000 | N27: =(L27*20%)+I27 -> 68500000 | O27: 66261000 | P27: =SUM(N27:O27) -> 134761000 | S27: 1 | Y27: =SUM(Q27:V27) -> 1 | Z27: =H27-Y27 -> 0 | AA27: =P27 -> 134761000 | AB27: =N27+O27-AA27 -> 0 | AD27: 45940 | AE27: =AD27+7 -> 45947 | AF27: =AE27+30 -> 45977 | AG27: =AE27+60 -> 46007 | AI27: Close | AK27: =VLOOKUP(C27,investasi!$B$23:$G$26,6,0)+investasi!I24 -> 134761000 | AL27: =P27 -> 134761000 | AM27: =AK27-AL27 -> 0
D28: Close | E28: =P28-AB28 -> 0 | F28: =L28-AC28 -> 0 | Y28: =SUM(Q28:V28) -> 0 | AA28: =P28 -> 0 | AI28: Close
A29: 18 | B29: 45965 | C29: =Detail!B60 -> 5200779815 | D29: Close | E29: =P29-AB29 -> 134761000 | F29: =L29-AC29 -> 342500000 | G29: Top Frame 2630 | H29: 1 | J29: =Detail!F60 -> 685000000 | K29: =H29*J29 -> 685000000 | L29: =K29*50% -> 342500000 | M29: =(L29*20%)/H29 -> 68500000 | N29: =(L29*20%)+I29 -> 68500000 | O29: 66261000 | P29: =SUM(N29:O29) -> 134761000 | U29: 1 | Y29: =SUM(Q29:V29) -> 1 | Z29: =H29-Y29 -> 0 | AA29: =P29 -> 134761000 | AB29: =N29+O29-AA29 -> 0 | AD29: 45989 | AE29: 46008 | AF29: 46034 | AG29: =AE29+30 -> 46038 | AH29: 46034 | AI29: Close | AJ29: Payment 12 Jan 2026 | AK29: =VLOOKUP(C29,investasi!$B$23:$G$26,6,0)+investasi!I26 -> 134761000 | AL29: =P29 -> 134761000 | AM29: =AK29-AL29 -> 0
A30: =A29+1 -> 19 | B30: 45977 | C30: 5200988854 | D30: Close | E30: =P30-AB30 -> 74857500 | F30: =L30-AC30 -> 374287500 | G30: Trench Grade | H30: 150 | J30: 4990500 | K30: =H30*J30 -> 748575000 | L30: =K30*50% -> 374287500 | M30: =(L30*20%)/H30 -> 499050 | N30: =(L30*20%)+I30 -> 74857500 | P30: =SUM(N30:O30) -> 74857500 | U30: 150 | Y30: =SUM(Q30:V30) -> 150 | Z30: =H30-Y30 -> 0 | AA30: =P30 -> 74857500 | AB30: =N30+O30-AA30 -> 0 | AD30: 45989 | AE30: 46008 | AF30: 46034 | AG30: =AE30+30 -> 46038 | AH30: 46034 | AI30: Close | AJ30: Payment 12 Jan 2026 | AN30: Tanki
A31: =A30+1 -> 20 | B31: 45977 | C31: 5200989664 | D31: Close | E31: =P31-AB31 -> 0 | F31: =L31-AC31 -> 0 | G31: Grating Ditch | H31: 50 | J31: 21100000 | K31: =H31*J31 -> 1055000000 | L31: =K31*50% -> 527500000 | M31: =(L31*20%)/H31 -> 2110000 | N31: =(L31*20%) -> 105500000 | P31: =SUM(N31:O31) -> 105500000 | V31: 50 | Y31: =SUM(Q31:V31) -> 50 | Z31: =H31-Y31 -> 0 | AA31: =P31 -> 105500000 | AB31: =AA31 -> 105500000 | AC31: =L31 -> 527500000 | AD31: 46031 | AE31: 46031 | AF31: =AD31+30 -> 46061 | AI31: Delivered
D32: Open | E32: =P32-AB32 -> 0 | F32: =L32-AC32 -> 0 | G32: Grating Ditch | H32: 50 | J32: 21100000 | K32: =H32*J32 -> 1055000000 | L32: =K32*50% -> 527500000 | M32: =(L32*20%)/H32 -> 2110000 | N32: =(L32*20%)+I32 -> 105500000 | P32: =SUM(N32:O32) -> 105500000 | W32: 50 | Y32: =SUM(Q32:V32) -> 0 | Z32: =H32-Y32 -> 50 | AA32: =P32 -> 105500000 | AB32: =AA32 -> 105500000 | AC32: =L32 -> 527500000 | AD32: 46031 | AE32: 46031 | AF32: =AD32+30 -> 46061 | AI32: Delivered
A33: =A31+1 -> 21 | B33: 45977 | C33: 5200989665 | D33: Delivered | E33: =P33-AB33 -> 0 | F33: =L33-AC33 -> 0 | G33: Grating Ditch | H33: 50 | J33: 21100000 | K33: =H33*J33 -> 1055000000 | L33: =K33*50% -> 527500000 | M33: =(L33*20%)/H33 -> 2110000 | N33: =(L33*20%)+I33 -> 105500000 | P33: =SUM(N33:O33) -> 105500000 | W33: 50 | Y33: =SUM(Q33:W33) -> 50 | Z33: =H33-Y33 -> 0 | AA33: =P33 -> 105500000 | AB33: =AA33 -> 105500000 | AC33: =L33 -> 527500000 | AD33: 46030 | AE33: 46030 | AF33: =AD33+30 -> 46060 | AI33: Delivered
A34: =A32+1 -> 1 | B34: 45977 | C34: 5200989665 | D34: Delivered | E34: =P34-AB34 -> 0 | F34: =L34-AC34 -> 527500000 | G34: Grating Ditch | H34: 50 | J34: 21100000 | K34: =H34*J34 -> 1055000000 | L34: =K34*50% -> 527500000 | M34: =(L34*20%)/H34 -> 2110000 | N34: =(L34*20%)+I34 -> 105500000 | P34: =SUM(N34:O34) -> 105500000 | Y34: =SUM(Q34:W34) -> 0 | Z34: =H34-Y34 -> 50 | AA34: =P34 -> 105500000 | AB34: =AA34 -> 105500000 | AD34: 46030 | AE34: 46030 | AF34: =AD34+30 -> 46060 | AI34: Delivered
A35: =A33+1 -> 22 | B35: 45977 | C35: 5200989666 | D35: Close | E35: =P35-AB35 -> 232100000 | F35: =L35-AC35 -> 1160500000 | G35: Grating Ditch | H35: 110 | J35: 21100000 | K35: =H35*J35 -> 2321000000 | L35: =K35*50% -> 1160500000 | M35: =(L35*20%)/H35 -> 2110000 | N35: =(L35*20%)+I35 -> 232100000 | P35: =SUM(N35:O35) -> 232100000 | W35: 110 | Y35: =SUM(Q35:W35) -> 110 | Z35: 0 | AA35: =P35 -> 232100000 | AD35: 46027 | AE35: 45676 | AF35: =AE35+30 -> 45706 | AI35: Delivered | AJ35: Partial Deliv 55 ea
A36: =A35+1 -> 23 | B36: 45981 | C36: 5200992759 | D36: Open | E36: =P36-AB36 -> 0 | F36: =L36-AC36 -> 0 | G36: Tanki | H36: 6 | J36: 100500000 | K36: =H36*J36 -> 603000000 | L36: =K36*50% -> 301500000 | M36: 10050000 | N36: =M36*H36 -> 60300000 | P36: =SUM(N36:O36) -> 60300000 | W36: 6 | Y36: =SUM(Q36:W36) -> 6 | Z36: =H36-Y36 -> 0 | AA36: =P36 -> 60300000 | AB36: =AA36 -> 60300000 | AC36: =L36 -> 301500000 | AD36: 46048 | AE36: 46048 | AF36: =AE36+30 -> 46078 | AI36: Delivered | AJ36: ada kenaikan harga material
A37: =A36+1 -> 24 | B37: 45985 | C37: 5200991260 | D37: Open | E37: =P37-AB37 -> 0 | F37: =L37-AC37 -> 0 | G37: Trench Grade | H37: 150 | J37: 4990500 | K37: =H37*J37 -> 748575000 | L37: =K37*50% -> 374287500 | M37: =(L37*20%)/H37 -> 499050 | N37: =(L37*20%)+I37 -> 74857500 | P37: =SUM(N37:O37) -> 74857500 | W37: =H37 -> 150 | Y37: =SUM(Q37:W37) -> 150 | Z37: =H37-Y37 -> 0 | AA37: =P37 -> 74857500 | AB37: =AA37 -> 74857500 | AC37: =L37 -> 374287500 | AD37: 46041 | AE37: 46041 | AG37: =AD37+60 -> 46101 | AI37: Delivered | AJ37: Terkirim
A38: =A37+1 -> 25 | B38: 45985 | C38: 5200991264 | D38: Open | E38: =P38-AB38 -> 0 | F38: =L38-AC38 -> 0 | G38: Trench Grade | H38: 150 | J38: 4990500 | K38: =H38*J38 -> 748575000 | L38: =K38*50% -> 374287500 | M38: =(L38*20%)/H38 -> 499050 | N38: =(L38*20%)+I38 -> 74857500 | P38: =SUM(N38:O38) -> 74857500 | W38: =H38 -> 150 | Y38: =SUM(Q38:W38) -> 150 | Z38: =H38-Y38 -> 0 | AA38: =P38 -> 74857500 | AB38: =AA38 -> 74857500 | AC38: =L38 -> 374287500 | AD38: 46041 | AE38: 46041 | AG38: =AD38+60 -> 46101 | AI38: Delivered | AJ38: Terkirim
A39: =A38+1 -> 26 | B39: 45986 | C39: 5200991456 | D39: Open | E39: =P39-AB39 -> 0 | F39: =L39-AC39 -> 0 | G39: Trench Grade | H39: 150 | J39: 4990500 | K39: =H39*J39 -> 748575000 | L39: =K39*50% -> 374287500 | M39: =(L39*20%)/H39 -> 499050 | N39: =(L39*20%)+I39 -> 74857500 | P39: =SUM(N39:O39) -> 74857500 | V39: =H39 -> 150 | Y39: =SUM(Q39:V39) -> 150 | Z39: =H39-Y39 -> 0 | AA39: =P39 -> 74857500 | AB39: =AA39 -> 74857500 | AC39: =L39 -> 374287500 | AD39: 46036 | AE39: 46036 | AG39: =AD39+60 -> 46096 | AI39: Delivered
A40: =A39+1 -> 27 | B40: 45986 | C40: 5200991458 | D40: Open | E40: =P40-AB40 -> 0 | F40: =L40-AC40 -> 0 | G40: Trench Grade | H40: 150 | J40: 4990500 | K40: =H40*J40 -> 748575000 | L40: =K40*50% -> 374287500 | M40: =(L40*20%)/H40 -> 499050 | N40: =(L40*20%)+I40 -> 74857500 | P40: =SUM(N40:O40) -> 74857500 | V40: =H40 -> 150 | Y40: =SUM(Q40:V40) -> 150 | Z40: =H40-Y40 -> 0 | AA40: =P40 -> 74857500 | AB40: =AA40 -> 74857500 | AC40: =L40 -> 374287500 | AD40: 46036 | AE40: 46036 | AG40: =AD40+60 -> 46096 | AI40: Delivered
A41: =A40+1 -> 28 | B41: 45986 | C41: 5200991502 | D41: Open | E41: =P41-AB41 -> 0 | F41: =L41-AC41 -> 0 | G41: Trench Grade | H41: 150 | J41: 4990500 | K41: =H41*J41 -> 748575000 | L41: =K41*50% -> 374287500 | M41: =(L41*20%)/H41 -> 499050 | N41: =(L41*20%)+I41 -> 74857500 | P41: =SUM(N41:O41) -> 74857500 | V41: =H41 -> 150 | Y41: =SUM(Q41:V41) -> 150 | Z41: =H41-Y41 -> 0 | AA41: =P41 -> 74857500 | AB41: =AA41 -> 74857500 | AC41: =L41 -> 374287500 | AD41: 46030 | AE41: 46030 | AG41: =AD41+60 -> 46090 | AI41: Delivered
A42: =A41+1 -> 29 | B42: 45986 | C42: 5200991503 | D42: Open | E42: =P42-AB42 -> 0 | F42: =L42-AC42 -> 0 | G42: Trench Grade | H42: 150 | J42: 4990500 | K42: =H42*J42 -> 748575000 | L42: =K42*50% -> 374287500 | M42: =(L42*20%)/H42 -> 499050 | N42: =(L42*20%)+I42 -> 74857500 | P42: =SUM(N42:O42) -> 74857500 | V42: =H42 -> 150 | Y42: =SUM(Q42:V42) -> 150 | Z42: =H42-Y42 -> 0 | AA42: =P42 -> 74857500 | AB42: =AA42 -> 74857500 | AC42: =L42 -> 374287500 | AD42: 46030 | AE42: 46030 | AG42: =AD42+60 -> 46090 | AI42: Delivered
A43: =A42+1 -> 30 | B43: 46372 | C43: 5200991553 | D43: Open | E43: =P43-AB43 -> 0 | F43: =L43-AC43 -> 0 | G43: Trench Grade | H43: 50 | J43: 4990500 | K43: =H43*J43 -> 249525000 | L43: =K43*50% -> 124762500 | M43: =(L43*20%)/H43 -> 499050 | N43: =(L43*20%)+I43 -> 24952500 | P43: =SUM(N43:O43) -> 24952500 | V43: =H43 -> 50 | Y43: =SUM(Q43:V43) -> 50 | Z43: =H43-Y43 -> 0 | AA43: =P43 -> 24952500 | AB43: =AA43 -> 24952500 | AC43: =L43 -> 124762500 | AD43: 46036 | AE43: 46036 | AG43: =AD43+60 -> 46096 | AI43: Delivered
A44: =A43+1 -> 31 | B44: 46021 | C44: 5200996833 | D44: Open | E44: =P44-AB44 -> 0 | F44: =L44-AC44 -> 0 | G44: new barge landing facility | H44: 1 | J44: 1188000000 | K44: 1188925400 | L44: =K44*50% -> 594462700 | M44: =(L44*20%)/H44 -> 118892540 | N44: =(L44*20%)+I44 -> 118892540 | P44: =SUM(N44:O44) -> 118892540 | Y44: 0 | Z44: 0 | AA44: =P44 -> 118892540 | AB44: =AA44 -> 118892540 | AC44: =L44 -> 594462700 | AI44: Open | AJ44: Blm Terkirim
B45: 46044 | C45: 5201004137 | D45: Open | G45: Marine Maintenance Jetty | H45: 1 | J45: 926640000 | K45: =H45*J45 -> 926640000 | L45: =K45*50% -> 463320000 | M45: =L45*20% -> 92664000 | N45: =(L45*20%)+I45 -> 92664000 | P45: =SUM(N45:O45) -> 92664000 | Y45: 0 | Z45: 0 | AB45: =N45+O45-AA45 -> 92664000 | AC45: =L45 -> 463320000 | AI45: Open | AJ45: Blm Terkirim
B46: 46045 | C46: 5201004344 | D46: Open | G46: Trench Grade | H46: 50 | J46: =249525000/H46 -> 4990500 | K46: =H46*J46 -> 249525000 | L46: =K46*50% -> 124762500 | M46: =(L46/H46)*20% -> 499050 | N46: =(L46*20%)+I46 -> 24952500 | P46: =SUM(N46:O46) -> 24952500 | Y46: 0 | Z46: 0 | AA46: 0 | AB46: =N46+O46-AA46 -> 24952500 | AC46: =L46 -> 124762500 | AI46: Open | AJ46: Blm Terkirim
B47: 46051 | C47: 5201005549 | D47: Open | G47: Top Frame 800 | H47: 2 | J47: 225000000 | K47: =H47*J47 -> 450000000 | L47: =K47*50% -> 225000000 | M47: =(L47/H47)*20% -> 22500000 | N47: =M47*H47 -> 45000000 | P47: =SUM(N47:O47) -> 45000000 | Y47: 0 | Z47: 0 | AA47: 0 | AB47: =N47+O47-AA47 -> 45000000 | AC47: =L47 -> 225000000 | AJ47: Blm Terkirim
...

Sheet Summary V.4 (5)
C1: LIST INVESTASI
H7: =Detail!E2 -> 4 | J7: =Detail!F2 -> 5 | K7: =Detail!G2 -> 6 | L7: =Detail!H2 -> 7 | N7: =Detail!I2 -> 8
A10: NO | B10: Date | C10: No. PO | D10: Status | E10: Margin Diterima | F10: Modal Di terima | G10: Nama Barang | H10: =Detail!E3 -> Qty | I10: Harga Beli (only added if Margin is set) | J10: =Detail!F3 -> Harga | K10: Total PO | L10: Modal | M10: Margin Per Unit | N10: =Detail!I3 -> Margin | O10: Add Margin | P10: Total Margin | Q10: Invoice /DO | Y10: DO Total | Z10: DO Outstanding | AA10: Margin | AB10: Margin ditahan | AC10: MODAL DITAHAN | AD10: Del Time | AE10: Invoice date | AF10: adjusting TOP 30 Days | AG10: adjusting TOP 60 Days | AH10: Payment Date | AI10: Status | AJ10: Notes | AK10: Tari | AL10: Total Margin TARI | AM10: Selisih
Q11: Jul | R11: Aug | S11: Sep | T11: Oct | U11: Nov | V11: Dec | W11: Jan | X11: Add Margin (by Agreement) | AJ11: Notes
A12: 1 | B12: =VLOOKUP($C12,Detail!$B$4:$Q$21,2,0) -> 45839 | C12: 5200954145 | D12: Close | E12: =P12-AB12 -> 45000000 | F12: =L12-AC12 -> 225000000 | G12: Top Frame 800 | H12: =SUMIF(Detail!$B$4:$B$21,'Summary V.4 (5)'!$C12,Detail!$E$4:$E$21) -> 2 | J12: =VLOOKUP($C12,Detail!$B$4:$Q$21,5,0) -> 225000000 | K12: =H12*J12 -> 450000000 | L12: =SUMIF(Detail!$B$4:$B$21,'Summary V.4 (5)'!C12,Detail!$H$4:$H$21) -> 225000000 | M12: =(L12*20%)/H12 -> 22500000 | N12: =L12*20% -> 45000000 | P12: =SUM(N12:O12) -> 45000000 | Q12: =H12 -> 2 | Y12: =SUM(Q12:V12) -> 2 | Z12: =H12-Y12 -> 0 | AA12: =M12*Y12 -> 45000000 | AB12: =N12-AA12 -> 0 | AD12: 45861 | AE12: 45863 | AF12: 45894 | AI12: Close | AK12: =VLOOKUP(C12,investasi!$B$5:$G$18,6,0) -> 45000000 | AL12: =P12 -> 45000000 | AM12: =AK12-AL12 -> 0
A13: 2 | B13: =VLOOKUP($C13,Detail!$B$4:$Q$21,2,0) -> 45839 | C13: 5200954149 | D13: Close | E13: =P13-AB13 -> 67500000 | F13: =L13-AC13 -> 337500000 | G13: Top Frame 800 | H13: =SUMIF(Detail!$B$4:$B$21,'Summary V.4 (5)'!$C13,Detail!$E$4:$E$21) -> 3 | J13: =VLOOKUP($C13,Detail!$B$4:$Q$21,5,0) -> 225000000 | K13: =H13*J13 -> 675000000 | L13: =SUMIF(Detail!$B$4:$B$21,'Summary V.4 (5)'!C13,Detail!$H$4:$H$21) -> 337500000 | M13: =(L13*20%)/H13 -> 22500000 | N13: =L13*20% -> 67500000 | P13: =SUM(N13:O13) -> 67500000 | Q13: =H13 -> 3 | Y13: =SUM(Q13:V13) -> 3 | Z13: =H13-Y13 -> 0 | AA13: =M13*Y13 -> 67500000 | AB13: =N13-AA13 -> 0 | AD13: 45861 | AE13: 45863 | AF13: 45894 | AI13: Close | AK13: =VLOOKUP(C13,investasi!$B$5:$G$18,6,0) -> 67500000 | AL13: =P13 -> 67500000 | AM13: =AK13-AL13 -> 0
A14: 3 | B14: =VLOOKUP($C14,Detail!$B$4:$Q$21,2,0) -> 45839 | C14: 5200954160 | D14: Close | E14: =P14-AB14 -> 67500000 | F14: =L14-AC14 -> 337500000 | G14: Top Frame 800 | H14: =SUMIF(Detail!$B$4:$B$21,'Summary V.4 (5)'!$C14,Detail!$E$4:$E$21) -> 3 | J14: =VLOOKUP($C14,Detail!$B$4:$Q$21,5,0) -> 225000000 | K14: =H14*J14 -> 675000000 | L14: =SUMIF(Detail!$B$4:$B$21,'Summary V.4 (5)'!C14,Detail!$H$4:$H$21) -> 337500000 | M14: =(L14*20%)/H14 -> 22500000 | N14: =L14*20% -> 67500000 | P14: =SUM(N14:O14) -> 67500000 | Q14: =H14 -> 3 | Y14: =SUM(Q14:V14) -> 3 | Z14: =H14-Y14 -> 0 | AA14: =M14*Y14 -> 67500000 | AB14: =N14-AA14 -> 0 | AD14: 45861 | AE14: 45863 | AF14: 45894 | AI14: Close | AK14: =VLOOKUP(C14,investasi!$B$5:$G$18,6,0) -> 67500000 | AL14: =P14 -> 67500000 | AM14: =AK14-AL14 -> 0
A15: 4 | B15: =VLOOKUP($C15,Detail!$B$4:$Q$21,2,0) -> 45870 | C15: 5200954165 | D15: Close | E15: =P15-AB15 -> 67500000 | F15: =L15-AC15 -> 337500000 | G15: Top Frame 800 | H15: =SUMIF(Detail!$B$4:$B$21,'Summary V.4 (5)'!$C15,Detail!$E$4:$E$21) -> 3 | J15: =VLOOKUP($C15,Detail!$B$4:$Q$21,5,0) -> 225000000 | K15: =H15*J15 -> 675000000 | L15: =SUMIF(Detail!$B$4:$B$21,'Summary V.4 (5)'!C15,Detail!$H$4:$H$21) -> 337500000 | M15: =(L15*20%)/H15 -> 22500000 | N15: =L15*20% -> 67500000 | P15: =SUM(N15:O15) -> 67500000 | R15: =H15 -> 3 | Y15: =SUM(Q15:V15) -> 3 | Z15: =H15-Y15 -> 0 | AA15: =M15*Y15 -> 67500000 | AB15: =N15-AA15 -> 0 | AD15: 45868 | AE15: 45873 | AF15: 45904 | AI15: Close | AK15: =VLOOKUP(C15,investasi!$B$5:$G$18,6,0) -> 67500000 | AL15: =P15 -> 67500000 | AM15: =AK15-AL15 -> 0
A16: 5 | B16: =VLOOKUP($C16,Detail!$B$4:$Q$21,2,0) -> 45870 | C16: 5200954167 | D16: Close | E16: =P16-AB16 -> 67500000 | F16: =L16-AC16 -> 337500000 | G16: Top Frame 800 | H16: =SUMIF(Detail!$B$4:$B$21,'Summary V.4 (5)'!$C16,Detail!$E$4:$E$21) -> 3 | J16: =VLOOKUP($C16,Detail!$B$4:$Q$21,5,0) -> 225000000 | K16: =H16*J16 -> 675000000 | L16: =SUMIF(Detail!$B$4:$B$21,'Summary V.4 (5)'!C16,Detail!$H$4:$H$21) -> 337500000 | M16: =(L16*20%)/H16 -> 22500000 | N16: =L16*20% -> 67500000 | P16: =SUM(N16:O16) -> 67500000 | R16: =H16 -> 3 | Y16: =SUM(Q16:V16) -> 3 | Z16: =H16-Y16 -> 0 | AA16: =M16*Y16 -> 67500000 | AB16: =N16-AA16 -> 0 | AD16: 45868 | AE16: 45873 | AF16: 45904 | AI16: Close | AK16: =VLOOKUP(C16,investasi!$B$5:$G$18,6,0) -> 67500000 | AL16: =P16 -> 67500000 | AM16: =AK16-AL16 -> 0
A17: 6 | B17: =VLOOKUP($C17,Detail!$B$4:$Q$21,2,0) -> 45870 | C17: 5200954168 | D17: Close | E17: =P17-AB17 -> 45000000 | F17: =L17-AC17 -> 225000000 | G17: Top Frame 800 | H17: =SUMIF(Detail!$B$4:$B$21,'Summary V.4 (5)'!$C17,Detail!$E$4:$E$21) -> 2 | J17: =VLOOKUP($C17,Detail!$B$4:$Q$21,5,0) -> 225000000 | K17: =H17*J17 -> 450000000 | L17: =SUMIF(Detail!$B$4:$B$21,'Summary V.4 (5)'!C17,Detail!$H$4:$H$21) -> 225000000 | M17: =(L17*20%)/H17 -> 22500000 | N17: =L17*20% -> 45000000 | P17: =SUM(N17:O17) -> 45000000 | R17: =H17 -> 2 | Y17: =SUM(Q17:V17) -> 2 | Z17: =H17-Y17 -> 0 | AA17: =M17*Y17 -> 45000000 | AB17: =N17-AA17 -> 0 | AD17: 45868 | AE17: 45873 | AF17: 45904 | AI17: Close | AK17: =VLOOKUP(C17,investasi!$B$5:$G$18,6,0) -> 45000000 | AL17: =P17 -> 45000000 | AM17: =AK17-AL17 -> 0
A18: 7 | B18: =VLOOKUP($C18,Detail!$B$4:$Q$21,2,0) -> 45870 | C18: 5200954169 | D18: Close | E18: =P18-AB18 -> 45000000 | F18: =L18-AC18 -> 225000000 | G18: Top Frame 800 | H18: =SUMIF(Detail!$B$4:$B$21,'Summary V.4 (5)'!$C18,Detail!$E$4:$E$21) -> 2 | J18: =VLOOKUP($C18,Detail!$B$4:$Q$21,5,0) -> 225000000 | K18: =H18*J18 -> 450000000 | L18: =SUMIF(Detail!$B$4:$B$21,'Summary V.4 (5)'!C18,Detail!$H$4:$H$21) -> 225000000 | M18: =(L18*20%)/H18 -> 22500000 | N18: =L18*20% -> 45000000 | P18: =SUM(N18:O18) -> 45000000 | R18: =H18 -> 2 | Y18: =SUM(Q18:V18) -> 2 | Z18: =H18-Y18 -> 0 | AA18: =M18*Y18 -> 45000000 | AB18: =N18-AA18 -> 0 | AD18: 45868 | AE18: 45873 | AF18: 45904 | AI18: Close | AK18: =VLOOKUP(C18,investasi!$B$5:$G$18,6,0) -> 45000000 | AL18: =P18 -> 45000000 | AM18: =AK18-AL18 -> 0
A19: 8 | B19: =VLOOKUP($C19,Detail!$B$4:$Q$25,2,0) -> 45877 | C19: 5200777098 | D19: Close | E19: =P19-AB19 -> 114919900 | F19: =L19-AC19 -> 574599500 | G19: DVAR 3771-B0-20D-PPC Statcom Steel Support | H19: =SUMIF(Detail!$B$4:$B$25,'Summary V.4 (5)'!$C19,Detail!$E$4:$E$25) -> 1 | J19: =VLOOKUP($C19,Detail!$B$4:$Q$25,5,0) -> 1149199000 | K19: =H19*J19 -> 1149199000 | L19: =SUMIF(Detail!$B$4:$B$25,'Summary V.4 (5)'!C19,Detail!$H$4:$H$25) -> 574599500 | M19: =(L19*20%)/H19 -> 114919900 | N19: =L19*20% -> 114919900 | P19: =SUM(N19:O19) -> 114919900 | R19: 0 | S19: 1 | Y19: =SUM(Q19:V19) -> 1 | Z19: =H19-Y19 -> 0 | AA19: =M19*Y19 -> 114919900 | AB19: =N19-AA19 -> 0 | AD19: 45930 | AE19: =AD19+7 -> 45937 | AF19: =AE19+30 -> 45967 | AG19: =AE19+60 -> 45997 | AI19: Close | AK19: =VLOOKUP(C19,investasi!$B$5:$G$18,6,0) -> 57248700 | AL19: =P19 -> 114919900 | AM19: =AK19-AL19 -> -57671200 | AN19: Selisih di unit Qty, di catatan pak mushafa 2 unit(1 sudah terbayar , 1 unit belum terbayar ), dicatatan TARI 1 Unit
